<?xml version="1.0" ?>
<!-- =================================================================================== -->
<!-- |    This document was autogenerated by xacro from robot.urdf.xacro               | -->
<!-- |    EDITING THIS FILE BY HAND IS NOT RECOMMENDED                                 | -->
<!-- =================================================================================== -->
<robot name="glam_bot_v2">
  <!-- MATERIALS -->
  <material name="hot_pink">
    <color rgba="1.0 0.41 0.7 1.0"/>
  </material>
  <material name="black">
    <color rgba="0.0 0.0 0.0 1.0"/>
  </material>
  <material name="yellow">
    <color rgba="1.0 1.0 0.0 1.0"/>
  </material>
  <!-- MACROS -->
  <!-- MAIN ROBOT STRUCTURE -->
  <!-- Base Footprint on Ground -->
  <link name="base_link"/>
  <!-- Body Link -->
  <link name="body_link">
    <visual>
      <geometry>
        <box size="0.6 0.4 0.2"/>
      </geometry>
      <material name="hot_pink"/>
    </visual>
    <collision>
      <geometry>
        <box size="0.6 0.4 0.2"/>
      </geometry>
    </collision>
    <inertial>
      <mass value="5.0"/>
      <inertia ixx="0.1" ixy="0.0" ixz="0.0" iyy="0.1" iyz="0.0" izz="0.1"/>
    </inertial>
  </link>
  <joint name="base_to_body" type="fixed">
    <parent link="base_link"/>
    <child link="body_link"/>
    <origin rpy="0 0 0" xyz="0 0 0.15"/>
  </joint>
  <!-- Cabin -->
  <link name="cabin_link">
    <visual>
      <geometry>
        <box size="0.3 0.35 0.15"/>
      </geometry>
      <material name="hot_pink"/>
    </visual>
    <collision>
      <geometry>
        <box size="0.3 0.35 0.15"/>
      </geometry>
    </collision>
    <inertial>
      <mass value="1.0"/>
      <inertia ixx="0.01" ixy="0.0" ixz="0.0" iyy="0.01" iyz="0.0" izz="0.01"/>
    </inertial>
  </link>
  <joint name="cabin_joint" type="fixed">
    <parent link="body_link"/>
    <child link="cabin_link"/>
    <origin rpy="0 0 0" xyz="-0.05 0 0.175"/>
  </joint>
  <link name="left_wheel">
    <visual>
      <geometry>
        <cylinder length="0.05" radius="0.1"/>
      </geometry>
      <material name="black"/>
      <origin rpy="1.5708 0 0"/>
    </visual>
    <collision>
      <geometry>
        <cylinder length="0.05" radius="0.1"/>
      </geometry>
      <origin rpy="1.5708 0 0"/>
    </collision>
    <inertial>
      <mass value="1.0"/>
      <inertia ixx="0.01" ixy="0.0" ixz="0.0" iyy="0.01" iyz="0.0" izz="0.01"/>
    </inertial>
  </link>
  <joint name="left_wheel_joint" type="continuous">
    <parent link="body_link"/>
    <child link="left_wheel"/>
    <!-- reflect is 1 for left and -1 for right -->
    <origin rpy="0 0 0" xyz="-0.15 0.225 -0.05"/>
    <axis xyz="0 1 0"/>
  </joint>
  <link name="right_wheel">
    <visual>
      <geometry>
        <cylinder length="0.05" radius="0.1"/>
      </geometry>
      <material name="black"/>
      <origin rpy="1.5708 0 0"/>
    </visual>
    <collision>
      <geometry>
        <cylinder length="0.05" radius="0.1"/>
      </geometry>
      <origin rpy="1.5708 0 0"/>
    </collision>
    <inertial>
      <mass value="1.0"/>
      <inertia ixx="0.01" ixy="0.0" ixz="0.0" iyy="0.01" iyz="0.0" izz="0.01"/>
    </inertial>
  </link>
  <joint name="right_wheel_joint" type="continuous">
    <parent link="body_link"/>
    <child link="right_wheel"/>
    <!-- reflect is 1 for left and -1 for right -->
    <origin rpy="0 0 0" xyz="-0.15 -0.225 -0.05"/>
    <axis xyz="0 1 0"/>
  </joint>
  <!-- Caster Wheel -->
  <link name="caster_wheel">
    <visual>
      <geometry>
        <sphere radius="0.05"/>
      </geometry>
      <material name="black"/>
    </visual>
    <collision>
      <geometry>
        <sphere radius="0.05"/>
      </geometry>
    </collision>
    <inertial>
      <mass value="0.5"/>
      <inertia ixx="0.001" ixy="0.0" ixz="0.0" iyy="0.001" iyz="0.0" izz="0.001"/>
    </inertial>
  </link>
  <joint name="caster_joint" type="fixed">
    <parent link="body_link"/>
    <child link="caster_wheel"/>
    <origin rpy="0 0 0" xyz="0.2 0 -0.1"/>
  </joint>
  <link name="left_eye">
    <visual>
      <geometry>
        <cylinder length="0.02" radius="0.06"/>
      </geometry>
      <material name="yellow"/>
      <origin rpy="0 1.5708 0"/>
    </visual>
    <inertial>
      <mass value="0.01"/>
      <inertia ixx="0.0001" ixy="0" ixz="0" iyy="0.0001" iyz="0" izz="0.0001"/>
    </inertial>
  </link>
  <joint name="left_eye_joint" type="fixed">
    <parent link="body_link"/>
    <child link="left_eye"/>
    <origin rpy="0 0 0" xyz="0.3 0.12 0.05"/>
  </joint>
  <link name="left_eye_lash_1">
    <visual>
      <geometry>
        <box size="0.01 0.005 0.05"/>
      </geometry>
      <material name="black"/>
    </visual>
    <inertial>
      <mass value="0.001"/>
      <inertia ixx="0" ixy="0" ixz="0" iyy="0" iyz="0" izz="0"/>
    </inertial>
  </link>
  <joint name="left_eye_lash_1_j" type="fixed">
    <parent link="left_eye"/>
    <child link="left_eye_lash_1"/>
    <origin rpy="0 0 0" xyz="0.01 0 0.05"/>
  </joint>
  <link name="left_eye_lash_2">
    <visual>
      <geometry>
        <box size="0.01 0.005 0.05"/>
      </geometry>
      <material name="black"/>
    </visual>
    <inertial>
      <mass value="0.001"/>
      <inertia ixx="0" ixy="0" ixz="0" iyy="0" iyz="0" izz="0"/>
    </inertial>
  </link>
  <joint name="left_eye_lash_2_j" type="fixed">
    <parent link="left_eye"/>
    <child link="left_eye_lash_2"/>
    <origin rpy="0 0 -0.3" xyz="0.01 0.03 0.05"/>
  </joint>
  <link name="left_eye_lash_3">
    <visual>
      <geometry>
        <box size="0.01 0.005 0.05"/>
      </geometry>
      <material name="black"/>
    </visual>
    <inertial>
      <mass value="0.001"/>
      <inertia ixx="0" ixy="0" ixz="0" iyy="0" iyz="0" izz="0"/>
    </inertial>
  </link>
  <joint name="left_eye_lash_3_j" type="fixed">
    <parent link="left_eye"/>
    <child link="left_eye_lash_3"/>
    <origin rpy="0 0 0.3" xyz="0.01 -0.03 0.05"/>
  </joint>
  <link name="right_eye">
    <visual>
      <geometry>
        <cylinder length="0.02" radius="0.06"/>
      </geometry>
      <material name="yellow"/>
      <origin rpy="0 1.5708 0"/>
    </visual>
    <inertial>
      <mass value="0.01"/>
      <inertia ixx="0.0001" ixy="0" ixz="0" iyy="0.0001" iyz="0" izz="0.0001"/>
    </inertial>
  </link>
  <joint name="right_eye_joint" type="fixed">
    <parent link="body_link"/>
    <child link="right_eye"/>
    <origin rpy="0 0 0" xyz="0.3 -0.12 0.05"/>
  </joint>
  <link name="right_eye_lash_1">
    <visual>
      <geometry>
        <box size="0.01 0.005 0.05"/>
      </geometry>
      <material name="black"/>
    </visual>
    <inertial>
      <mass value="0.001"/>
      <inertia ixx="0" ixy="0" ixz="0" iyy="0" iyz="0" izz="0"/>
    </inertial>
  </link>
  <joint name="right_eye_lash_1_j" type="fixed">
    <parent link="right_eye"/>
    <child link="right_eye_lash_1"/>
    <origin rpy="0 0 0" xyz="0.01 0 0.05"/>
  </joint>
  <link name="right_eye_lash_2">
    <visual>
      <geometry>
        <box size="0.01 0.005 0.05"/>
      </geometry>
      <material name="black"/>
    </visual>
    <inertial>
      <mass value="0.001"/>
      <inertia ixx="0" ixy="0" ixz="0" iyy="0" iyz="0" izz="0"/>
    </inertial>
  </link>
  <joint name="right_eye_lash_2_j" type="fixed">
    <parent link="right_eye"/>
    <child link="right_eye_lash_2"/>
    <origin rpy="0 0 0.3" xyz="0.01 0.03 0.05"/>
  </joint>
  <link name="right_eye_lash_3">
    <visual>
      <geometry>
        <box size="0.01 0.005 0.05"/>
      </geometry>
      <material name="black"/>
    </visual>
    <inertial>
      <mass value="0.001"/>
      <inertia ixx="0" ixy="0" ixz="0" iyy="0" iyz="0" izz="0"/>
    </inertial>
  </link>
  <joint name="right_eye_lash_3_j" type="fixed">
    <parent link="right_eye"/>
    <child link="right_eye_lash_3"/>
    <origin rpy="0 0 -0.3" xyz="0.01 -0.03 0.05"/>
  </joint>
</robot>
